2025-04-29 00:29:58.978555 - ERROR : send/read tcp data error: Traceback (most recent call last):
  File "D:\anaconda\envs\myenv\Lib\site-packages\PyAibote\Tool\SendTcpData.py", line 25, in SendData
    response = self.StarLoadWait(data)
               ^^^^^^^^^^^^^^^^^^^^^^^
  File "D:\anaconda\envs\myenv\Lib\site-packages\PyAibote\WindowsBotModel\WinLoadWait.py", line 42, in StarLoadWait
    response = self._Send(data)
               ^^^^^^^^^^^^^^^^
  File "D:\anaconda\envs\myenv\Lib\site-packages\PyAibote\WindowsBotModel\WinLoadWait.py", line 22, in _Send
    response = self.request.recv(87654)
               ^^^^^^^^^^^^^^^^^^^^^^^^
ConnectionResetError: [WinError 10054] 远程主机强迫关闭了一个现有的连接。

2025-04-29 00:31:57.346151 - ERROR : send/read tcp data error: Traceback (most recent call last):
  File "D:\anaconda\envs\myenv\Lib\site-packages\PyAibote\Tool\SendTcpData.py", line 25, in SendData
    response = self.StarLoadWait(data)
               ^^^^^^^^^^^^^^^^^^^^^^^
  File "D:\anaconda\envs\myenv\Lib\site-packages\PyAibote\WindowsBotModel\WinLoadWait.py", line 42, in StarLoadWait
    response = self._Send(data)
               ^^^^^^^^^^^^^^^^
  File "D:\anaconda\envs\myenv\Lib\site-packages\PyAibote\WindowsBotModel\WinLoadWait.py", line 22, in _Send
    response = self.request.recv(87654)
               ^^^^^^^^^^^^^^^^^^^^^^^^
ConnectionResetError: [WinError 10054] 远程主机强迫关闭了一个现有的连接。

2025-04-29 00:32:30.685046 - ERROR : send/read tcp data error: Traceback (most recent call last):
  File "D:\anaconda\envs\myenv\Lib\site-packages\PyAibote\Tool\SendTcpData.py", line 25, in SendData
    response = self.StarLoadWait(data)
               ^^^^^^^^^^^^^^^^^^^^^^^
  File "D:\anaconda\envs\myenv\Lib\site-packages\PyAibote\WindowsBotModel\WinLoadWait.py", line 42, in StarLoadWait
    response = self._Send(data)
               ^^^^^^^^^^^^^^^^
  File "D:\anaconda\envs\myenv\Lib\site-packages\PyAibote\WindowsBotModel\WinLoadWait.py", line 22, in _Send
    response = self.request.recv(87654)
               ^^^^^^^^^^^^^^^^^^^^^^^^
ConnectionResetError: [WinError 10054] 远程主机强迫关闭了一个现有的连接。

2025-04-29 00:40:33.959349 - ERROR : send/read tcp data error: Traceback (most recent call last):
  File "D:\anaconda\envs\myenv\Lib\site-packages\PyAibote\Tool\SendTcpData.py", line 25, in SendData
    response = self.StarLoadWait(data)
               ^^^^^^^^^^^^^^^^^^^^^^^
  File "D:\anaconda\envs\myenv\Lib\site-packages\PyAibote\WindowsBotModel\WinLoadWait.py", line 42, in StarLoadWait
    response = self._Send(data)
               ^^^^^^^^^^^^^^^^
  File "D:\anaconda\envs\myenv\Lib\site-packages\PyAibote\WindowsBotModel\WinLoadWait.py", line 22, in _Send
    response = self.request.recv(87654)
               ^^^^^^^^^^^^^^^^^^^^^^^^
ConnectionResetError: [WinError 10054] 远程主机强迫关闭了一个现有的连接。

2025-04-29 00:53:50.508150 - ERROR : send/read tcp data error: Traceback (most recent call last):
  File "D:\anaconda\envs\myenv\Lib\site-packages\PyAibote\Tool\SendTcpData.py", line 25, in SendData
    response = self.StarLoadWait(data)
               ^^^^^^^^^^^^^^^^^^^^^^^
  File "D:\anaconda\envs\myenv\Lib\site-packages\PyAibote\WindowsBotModel\WinLoadWait.py", line 42, in StarLoadWait
    response = self._Send(data)
               ^^^^^^^^^^^^^^^^
  File "D:\anaconda\envs\myenv\Lib\site-packages\PyAibote\WindowsBotModel\WinLoadWait.py", line 22, in _Send
    response = self.request.recv(87654)
               ^^^^^^^^^^^^^^^^^^^^^^^^
ConnectionResetError: [WinError 10054] 远程主机强迫关闭了一个现有的连接。

2025-04-29 00:55:59.501601 - ERROR : send/read tcp data error: Traceback (most recent call last):
  File "D:\anaconda\envs\myenv\Lib\site-packages\PyAibote\Tool\SendTcpData.py", line 25, in SendData
    response = self.StarLoadWait(data)
               ^^^^^^^^^^^^^^^^^^^^^^^
  File "D:\anaconda\envs\myenv\Lib\site-packages\PyAibote\WindowsBotModel\WinLoadWait.py", line 42, in StarLoadWait
    response = self._Send(data)
               ^^^^^^^^^^^^^^^^
  File "D:\anaconda\envs\myenv\Lib\site-packages\PyAibote\WindowsBotModel\WinLoadWait.py", line 22, in _Send
    response = self.request.recv(87654)
               ^^^^^^^^^^^^^^^^^^^^^^^^
ConnectionResetError: [WinError 10054] 远程主机强迫关闭了一个现有的连接。

2025-04-29 00:56:02.690685 - ERROR : send/read tcp data error: Traceback (most recent call last):
  File "D:\anaconda\envs\myenv\Lib\site-packages\PyAibote\Tool\SendTcpData.py", line 25, in SendData
    response = self.StarLoadWait(data)
               ^^^^^^^^^^^^^^^^^^^^^^^
  File "D:\anaconda\envs\myenv\Lib\site-packages\PyAibote\WindowsBotModel\WinLoadWait.py", line 42, in StarLoadWait
    response = self._Send(data)
               ^^^^^^^^^^^^^^^^
  File "D:\anaconda\envs\myenv\Lib\site-packages\PyAibote\WindowsBotModel\WinLoadWait.py", line 21, in _Send
    self.request.sendall(data)
OSError: [WinError 10038] 在一个非套接字上尝试了一个操作。

2025-04-29 00:56:05.852900 - ERROR : send/read tcp data error: Traceback (most recent call last):
  File "D:\anaconda\envs\myenv\Lib\site-packages\PyAibote\Tool\SendTcpData.py", line 25, in SendData
    response = self.StarLoadWait(data)
               ^^^^^^^^^^^^^^^^^^^^^^^
  File "D:\anaconda\envs\myenv\Lib\site-packages\PyAibote\WindowsBotModel\WinLoadWait.py", line 42, in StarLoadWait
    response = self._Send(data)
               ^^^^^^^^^^^^^^^^
  File "D:\anaconda\envs\myenv\Lib\site-packages\PyAibote\WindowsBotModel\WinLoadWait.py", line 21, in _Send
    self.request.sendall(data)
OSError: [WinError 10038] 在一个非套接字上尝试了一个操作。

2025-04-29 00:58:26.075480 - ERROR : send/read tcp data error: Traceback (most recent call last):
  File "D:\anaconda\envs\myenv\Lib\site-packages\PyAibote\Tool\SendTcpData.py", line 25, in SendData
    response = self.StarLoadWait(data)
               ^^^^^^^^^^^^^^^^^^^^^^^
  File "D:\anaconda\envs\myenv\Lib\site-packages\PyAibote\WindowsBotModel\WinLoadWait.py", line 42, in StarLoadWait
    response = self._Send(data)
               ^^^^^^^^^^^^^^^^
  File "D:\anaconda\envs\myenv\Lib\site-packages\PyAibote\WindowsBotModel\WinLoadWait.py", line 22, in _Send
    response = self.request.recv(87654)
               ^^^^^^^^^^^^^^^^^^^^^^^^
ConnectionResetError: [WinError 10054] 远程主机强迫关闭了一个现有的连接。

2025-04-29 00:58:26.445261 - ERROR : send/read tcp data error: Traceback (most recent call last):
  File "D:\anaconda\envs\myenv\Lib\site-packages\PyAibote\Tool\SendTcpData.py", line 25, in SendData
    response = self.StarLoadWait(data)
               ^^^^^^^^^^^^^^^^^^^^^^^
  File "D:\anaconda\envs\myenv\Lib\site-packages\PyAibote\WindowsBotModel\WinLoadWait.py", line 42, in StarLoadWait
    response = self._Send(data)
               ^^^^^^^^^^^^^^^^
  File "D:\anaconda\envs\myenv\Lib\site-packages\PyAibote\WindowsBotModel\WinLoadWait.py", line 21, in _Send
    self.request.sendall(data)
OSError: [WinError 10038] 在一个非套接字上尝试了一个操作。

2025-04-29 00:58:28.416327 - ERROR : send/read tcp data error: Traceback (most recent call last):
  File "D:\anaconda\envs\myenv\Lib\site-packages\PyAibote\Tool\SendTcpData.py", line 25, in SendData
    response = self.StarLoadWait(data)
               ^^^^^^^^^^^^^^^^^^^^^^^
  File "D:\anaconda\envs\myenv\Lib\site-packages\PyAibote\WindowsBotModel\WinLoadWait.py", line 42, in StarLoadWait
    response = self._Send(data)
               ^^^^^^^^^^^^^^^^
  File "D:\anaconda\envs\myenv\Lib\site-packages\PyAibote\WindowsBotModel\WinLoadWait.py", line 22, in _Send
    response = self.request.recv(87654)
               ^^^^^^^^^^^^^^^^^^^^^^^^
ConnectionResetError: [WinError 10054] 远程主机强迫关闭了一个现有的连接。

2025-04-29 00:58:28.650788 - ERROR : send/read tcp data error: Traceback (most recent call last):
  File "D:\anaconda\envs\myenv\Lib\site-packages\PyAibote\Tool\SendTcpData.py", line 25, in SendData
    response = self.StarLoadWait(data)
               ^^^^^^^^^^^^^^^^^^^^^^^
  File "D:\anaconda\envs\myenv\Lib\site-packages\PyAibote\WindowsBotModel\WinLoadWait.py", line 42, in StarLoadWait
    response = self._Send(data)
               ^^^^^^^^^^^^^^^^
  File "D:\anaconda\envs\myenv\Lib\site-packages\PyAibote\WindowsBotModel\WinLoadWait.py", line 21, in _Send
    self.request.sendall(data)
OSError: [WinError 10038] 在一个非套接字上尝试了一个操作。

2025-04-29 00:58:29.891666 - ERROR : send/read tcp data error: Traceback (most recent call last):
  File "D:\anaconda\envs\myenv\Lib\site-packages\PyAibote\Tool\SendTcpData.py", line 25, in SendData
    response = self.StarLoadWait(data)
               ^^^^^^^^^^^^^^^^^^^^^^^
  File "D:\anaconda\envs\myenv\Lib\site-packages\PyAibote\WindowsBotModel\WinLoadWait.py", line 42, in StarLoadWait
    response = self._Send(data)
               ^^^^^^^^^^^^^^^^
  File "D:\anaconda\envs\myenv\Lib\site-packages\PyAibote\WindowsBotModel\WinLoadWait.py", line 21, in _Send
    self.request.sendall(data)
OSError: [WinError 10038] 在一个非套接字上尝试了一个操作。

2025-04-29 00:58:31.826269 - ERROR : send/read tcp data error: Traceback (most recent call last):
  File "D:\anaconda\envs\myenv\Lib\site-packages\PyAibote\Tool\SendTcpData.py", line 25, in SendData
    response = self.StarLoadWait(data)
               ^^^^^^^^^^^^^^^^^^^^^^^
  File "D:\anaconda\envs\myenv\Lib\site-packages\PyAibote\WindowsBotModel\WinLoadWait.py", line 42, in StarLoadWait
    response = self._Send(data)
               ^^^^^^^^^^^^^^^^
  File "D:\anaconda\envs\myenv\Lib\site-packages\PyAibote\WindowsBotModel\WinLoadWait.py", line 21, in _Send
    self.request.sendall(data)
OSError: [WinError 10038] 在一个非套接字上尝试了一个操作。

2025-04-29 01:06:59.958327 - ERROR : send/read tcp data error: Traceback (most recent call last):
  File "D:\anaconda\envs\myenv\Lib\site-packages\PyAibote\Tool\SendTcpData.py", line 25, in SendData
    response = self.StarLoadWait(data)
               ^^^^^^^^^^^^^^^^^^^^^^^
  File "D:\anaconda\envs\myenv\Lib\site-packages\PyAibote\WindowsBotModel\WinLoadWait.py", line 42, in StarLoadWait
    response = self._Send(data)
               ^^^^^^^^^^^^^^^^
  File "D:\anaconda\envs\myenv\Lib\site-packages\PyAibote\WindowsBotModel\WinLoadWait.py", line 22, in _Send
    response = self.request.recv(87654)
               ^^^^^^^^^^^^^^^^^^^^^^^^
ConnectionResetError: [WinError 10054] 远程主机强迫关闭了一个现有的连接。

2025-04-29 01:10:03.287316 - ERROR : send/read tcp data error: Traceback (most recent call last):
  File "D:\anaconda\envs\myenv\Lib\site-packages\PyAibote\Tool\SendTcpData.py", line 25, in SendData
    response = self.StarLoadWait(data)
               ^^^^^^^^^^^^^^^^^^^^^^^
  File "D:\anaconda\envs\myenv\Lib\site-packages\PyAibote\WindowsBotModel\WinLoadWait.py", line 42, in StarLoadWait
    response = self._Send(data)
               ^^^^^^^^^^^^^^^^
  File "D:\anaconda\envs\myenv\Lib\site-packages\PyAibote\WindowsBotModel\WinLoadWait.py", line 22, in _Send
    response = self.request.recv(87654)
               ^^^^^^^^^^^^^^^^^^^^^^^^
ConnectionResetError: [WinError 10054] 远程主机强迫关闭了一个现有的连接。

2025-04-29 01:10:03.289323 - ERROR : send/read tcp data error: Traceback (most recent call last):
  File "D:\anaconda\envs\myenv\Lib\site-packages\PyAibote\Tool\SendTcpData.py", line 25, in SendData
    response = self.StarLoadWait(data)
               ^^^^^^^^^^^^^^^^^^^^^^^
  File "D:\anaconda\envs\myenv\Lib\site-packages\PyAibote\WindowsBotModel\WinLoadWait.py", line 42, in StarLoadWait
    response = self._Send(data)
               ^^^^^^^^^^^^^^^^
  File "D:\anaconda\envs\myenv\Lib\site-packages\PyAibote\WindowsBotModel\WinLoadWait.py", line 21, in _Send
    self.request.sendall(data)
OSError: [WinError 10038] 在一个非套接字上尝试了一个操作。

2025-04-29 01:10:03.290323 - ERROR : send/read tcp data error: Traceback (most recent call last):
  File "D:\anaconda\envs\myenv\Lib\site-packages\PyAibote\Tool\SendTcpData.py", line 25, in SendData
    response = self.StarLoadWait(data)
               ^^^^^^^^^^^^^^^^^^^^^^^
  File "D:\anaconda\envs\myenv\Lib\site-packages\PyAibote\WindowsBotModel\WinLoadWait.py", line 42, in StarLoadWait
    response = self._Send(data)
               ^^^^^^^^^^^^^^^^
  File "D:\anaconda\envs\myenv\Lib\site-packages\PyAibote\WindowsBotModel\WinLoadWait.py", line 21, in _Send
    self.request.sendall(data)
OSError: [WinError 10038] 在一个非套接字上尝试了一个操作。

2025-04-29 01:10:03.291322 - ERROR : send/read tcp data error: Traceback (most recent call last):
  File "D:\anaconda\envs\myenv\Lib\site-packages\PyAibote\Tool\SendTcpData.py", line 25, in SendData
    response = self.StarLoadWait(data)
               ^^^^^^^^^^^^^^^^^^^^^^^
  File "D:\anaconda\envs\myenv\Lib\site-packages\PyAibote\WindowsBotModel\WinLoadWait.py", line 42, in StarLoadWait
    response = self._Send(data)
               ^^^^^^^^^^^^^^^^
  File "D:\anaconda\envs\myenv\Lib\site-packages\PyAibote\WindowsBotModel\WinLoadWait.py", line 21, in _Send
    self.request.sendall(data)
OSError: [WinError 10038] 在一个非套接字上尝试了一个操作。

2025-04-29 01:10:03.292323 - ERROR : send/read tcp data error: Traceback (most recent call last):
  File "D:\anaconda\envs\myenv\Lib\site-packages\PyAibote\Tool\SendTcpData.py", line 25, in SendData
    response = self.StarLoadWait(data)
               ^^^^^^^^^^^^^^^^^^^^^^^
  File "D:\anaconda\envs\myenv\Lib\site-packages\PyAibote\WindowsBotModel\WinLoadWait.py", line 42, in StarLoadWait
    response = self._Send(data)
               ^^^^^^^^^^^^^^^^
  File "D:\anaconda\envs\myenv\Lib\site-packages\PyAibote\WindowsBotModel\WinLoadWait.py", line 21, in _Send
    self.request.sendall(data)
OSError: [WinError 10038] 在一个非套接字上尝试了一个操作。

